<?xml version="1.0" ?>
<robot name="IRL_dual_arm">

<!--==========RIGHT ARM==============-->
<!--		 base 		-->
<link name="base">
    <collision>
    <origin rpy="0 0 0" xyz="0 0 0.05"/>
      	<geometry>
        <mesh filename="package://irl_dual_arm/mesh/arm/base.dae" scale="1 1 1"/>
      	</geometry>
    </collision>
    <visual>
    <origin rpy="0 0 0" xyz="0 0 0.05"/>
 	<geometry>
        <mesh filename="package://irl_dual_arm/mesh/arm/base.dae" scale="1 1 1"/>
      </geometry>
    </visual>
  </link>

  <joint name="joint1" type="revolute">
    <parent link="base"/>
    <child link="link1"/>
    <origin rpy="1.571 0 1.571" xyz="0.19 0 0.88"/>
    <axis xyz="0 0 1"/> 
    <limit effort="30" lower="-1.0467" upper="3.14" velocity="1.571"/>
  </joint>

<!-- 		link1 		-->
  <link name="link1">
    <collision>
      <origin rpy="0 0 1.571" xyz="0 0 0"/>
      <geometry>
        <mesh filename="package://irl_dual_arm/mesh/arm/link1.dae" scale="1 1 1"/>
      </geometry>
    </collision>
    <visual>
      <origin rpy="0 0 1.571" xyz="0 0 0"/>
      <geometry>
        <mesh filename="package://irl_dual_arm/mesh/arm/link1.dae" scale="1 1 1"/>
      </geometry>
    </visual>
    <inertial>
      <origin rpy="0 0 1.571" xyz="0 0 0"/>
      <mass value="1"/>
      <inertia ixx="1.0" ixy="0.0" ixz="0.0" iyy="1.0" iyz="0.0" izz="1.0"/>
    </inertial>
  </link>

  <joint name="joint2" type="revolute">
    <parent link="link1"/>
    <child link="link2"/>
    <origin rpy="0 1.571 0" xyz="-0.04 0 0.06"/>
    <axis xyz="0 0 1"/>
    <limit effort="30" lower="-2.355" upper="0.3489" velocity="1.571"/>
  </joint>

<!-- link2 -->
  <link name="link2">
    <collision>
      <origin rpy="0 0 0" xyz="0 0 0"/>
       <geometry>
        <mesh filename="package://irl_dual_arm/mesh/arm/link2.dae" scale="1 1 1"/>
      </geometry>
    </collision>
    <visual>
      <origin rpy="0 0 0" xyz="0 0 0"/>
      <geometry>
        <mesh filename="package://irl_dual_arm/mesh/arm/link2.dae" scale="1 1 1"/>
      </geometry>
    </visual>
    <inertial>
      <origin rpy="0 0 0" xyz="0 0 0"/>
      <mass value="1"/>
      <inertia ixx="1.0" ixy="0.0" ixz="0.0" iyy="1.0" iyz="0.0" izz="1.0"/>
    </inertial>
  </link>

  <joint name="joint3" type="revolute">
    <parent link="link2"/>
    <child link="link3"/>
    <origin rpy="1.571 0 0" xyz="0 -0.04 0.035"/>		
    <axis xyz="0 0 1"/>
    <limit effort="30" lower="-1.74" upper="0.611" velocity="1.571"/>
  </joint>

<!-- link3 -->
  <link name="link3">
      <collision>
      <origin rpy="0 0 0" xyz="0 0 0"/>
       <geometry>
        <mesh filename="package://irl_dual_arm/mesh/arm/link3.dae" scale="1 1 1"/>
      </geometry>
    </collision>
    <visual>
      <origin rpy="0 0 3.14" xyz="0 0 0"/>
      <geometry>
        <mesh filename="package://irl_dual_arm/mesh/arm/link3.dae" scale="1 1 1"/>
      </geometry>
    </visual>
    <inertial>
      <origin rpy="0 0 0" xyz="0 0 0"/>
      <mass value="1"/>
      <inertia ixx="1.0" ixy="0.0" ixz="0.0" iyy="1.0" iyz="0.0" izz="1.0"/>
    </inertial>
  </link>


  <joint name="joint4" type="revolute">
    <parent link="link3"/>
    <child link="link4"/>
    <origin rpy="0 -1.571 0" xyz="-0.025 0 0.2"/>
    <axis xyz="0 0 1"/>
    <limit effort="30" lower="0" upper="1.8" velocity="1.571"/>
  </joint>

<!-- link4 -->
  <link name="link4">
      <collision>
      <origin rpy="0 0 0" xyz="0 0 0"/>
       <geometry>
        <mesh filename="package://irl_dual_arm/mesh/arm/link4.dae" scale="1 1 1"/>
      </geometry>
    </collision>
    <visual>
      <origin rpy="3.14 0 -1.571" xyz="0 0 0"/>
      <geometry>
        <mesh filename="package://irl_dual_arm/mesh/arm/link4.dae" scale="1 1 1"/>
      </geometry>
    </visual>
    <inertial>
      <origin rpy="0 0 0" xyz="0 0 0"/>
      <mass value="1"/>
      <inertia ixx="1.0" ixy="0.0" ixz="0.0" iyy="1.0" iyz="0.0" izz="1.0"/>
    </inertial>
  </link>

  <joint name="joint5" type="revolute">
    <parent link="link4"/>
    <child link="link5"/>
    <origin rpy="0 1.571 0" xyz="0.04 0 -0.025"/>
    <axis xyz="0 0 1"/>
    <limit effort="30" lower="-1.74" upper="1.74" velocity="1.571"/>
  </joint>

<!-- link5 -->
  <link name="link5">
       <collision>
      <origin rpy="0 0 0" xyz="0 0 0"/>
       <geometry>
        <mesh filename="package://irl_dual_arm/mesh/arm/link5.dae" scale="1 1 1"/>
      </geometry>
    </collision>
    <visual>
      <origin rpy="0 0 0" xyz="0 0 0"/>
      <geometry>
        <mesh filename="package://irl_dual_arm/mesh/arm/link5.dae" scale="1 1 1"/>
      </geometry>
    </visual>
    <inertial>
      <origin rpy="0 0 0" xyz="0 0 0"/>
      <mass value="1"/>
      <inertia ixx="1.0" ixy="0.0" ixz="0.0" iyy="1.0" iyz="0.0" izz="1.0"/>
    </inertial>
  </link>

<<<<<<< HEAD
<!-- robotis's 3DOF gripper -->

  <joint name="joint6" type="revolute">
    <parent link="link5"/>
    <child link="link6"/>
    <origin rpy="0 0 0" xyz="0 0 0"/>
=======
<!-- robotis's 3DOF gripper_RIGHT -->
  <joint name="joint6" type="fixed">
    <parent link="link5"/>
    <child link="gr_rbase"/>
    <origin rpy="-1.57 -1.57 0" xyz="0 0 0.19"/>
<!--
>>>>>>> master
    <axis xyz="0 0 1"/>
    <limit effort="30" lower="-1.74" upper="1.74" velocity="1.571"/>
-->
  </joint>

<<<<<<< HEAD
<!-- link6 -->
  <link name="link6">
       <collision>
      <origin rpy="0 0 0" xyz="0 0 0.25"/>
       <geometry>
        <box size = "0.1 0.1 0.5"/>
      </geometry>
    </collision>
    <visual>
      <origin rpy="0 0 0" xyz="0 0 0.25"/>
      <geometry>
        <box size = "0.1 0.1 0.5"/>
=======
  <link name="gr_rbase">
    <collision>
      <origin rpy="-1.57 0 -0.73" xyz="0 -0.028 0"/>
      <geometry>
        <mesh filename="package://irl_dual_arm/mesh/gripper/r_base.dae" scale="1 1 1"/>
      </geometry>
    </collision>
    <visual>
      <origin rpy="-1.57 0 -0.73" xyz="0 -0.028 0"/>
      <geometry>
        <mesh filename="package://irl_dual_arm/mesh/gripper/r_base.dae" scale="1 1 1"/>
      </geometry>
    </visual>
    <inertial>
      <origin rpy="0 0 0" xyz="0 0 0"/>
      <mass value="1"/>
      <inertia ixx="1.0" ixy="0.0" ixz="0.0" iyy="1.0" iyz="0.0" izz="1.0"/>
    </inertial>
  </link>

  <joint name="r_finger1_1" type="revolute">
    <parent link="gr_rbase"/>
    <child link="r_finger_1_1"/>
    <origin rpy="0 0 0" xyz="0.0475 -0.002 0.0285"/>
    <axis xyz="0 0 1"/>
    <limit effort="30" lower="0" upper="0.87" velocity="1.571"/>
  </joint>

  <link name="r_finger_1_1">
    <collision>
      <origin rpy="-1.57 0 -1.57" xyz="0 0 0"/>
      <geometry>
        <mesh filename="package://irl_dual_arm/mesh/gripper/r_1_1.dae" scale="1 1 1"/>
      </geometry>
    </collision>
    <visual>
      <origin rpy="-1.57 0 -1.57" xyz="0 0 0"/>
      <geometry>
        <mesh filename="package://irl_dual_arm/mesh/gripper/r_1_1.dae" scale="1 1 1"/>
      </geometry>
    </visual>
    <inertial>
      <origin rpy="0 0 0" xyz="0 0 0"/>
      <mass value="1"/>
      <inertia ixx="1.0" ixy="0.0" ixz="0.0" iyy="1.0" iyz="0.0" izz="1.0"/>
    </inertial>
  </link>

<!---->
  <joint name="r_finger1_2" type="revolute">
    <parent link="r_finger_1_1"/>
    <child link="r_finger_1_2"/>
    <origin rpy="0 0 0" xyz="0.05 -0.005 0"/>
    <axis xyz="0 0 1"/>
    <limit effort="30" lower="0" upper="1.4" velocity="1.571"/>
    <mimic joint="r_finger1_1" multiplier="1.6" offset="0" />
    <!-- gear ratio = 1.4/0.87 -->
  </joint>

  <link name="r_finger_1_2">
    <collision>
      <origin rpy="-1.57 0 -1.57" xyz="0 0 0"/>
      <geometry>
        <mesh filename="package://irl_dual_arm/mesh/gripper/r_1_2.dae" scale="0.001 0.001 0.001"/>
      </geometry>
    </collision>
    <visual>
      <origin rpy="-1.57 0 -1.57" xyz="0 0 -0.013"/>
      <geometry>
        <mesh filename="package://irl_dual_arm/mesh/gripper/r_1_2.dae" scale="0.001 0.001 0.001"/>
>>>>>>> master
      </geometry>
    </visual>
    <inertial>
      <origin rpy="0 0 0" xyz="0 0 0.25"/>
      <mass value="1"/>
      <inertia ixx="1.0" ixy="0.0" ixz="0.0" iyy="1.0" iyz="0.0" izz="1.0"/>
    </inertial>
  </link>

<<<<<<< HEAD
=======







>>>>>>> master
</robot>
