<?xml version="1.0" ?>
<robot  xmlns:xacro="http://www.ros.org/wiki/xacro"
	xmlns:interface="http://playerstage.sourceforge.net/gazebo/xmlschema/#interface"
	xmlns:controller="http://playerstage.sourceforge.net/gazebo/xmlschema/#controller"
	name="irl_dual_arm">

  <material name="Black">
    <color rgba="0.0 0.0 0.0 1.0"/>
  </material>
  <material name="Red">
    <color rgba="0.8 0.0 0.0 1.0"/>
  </material>
  <material name="White">
    <color rgba="1.0 1.0 1.0 1.0"/>
  </material>

  <xacro:macro name="inertial_matrix" params="mass">
    <inertial>
       <mass value="${mass}" />
       <inertia ixx="0.5" ixy="0.0" ixz="0.0"
                iyy="0.5" iyz="0.0"
                izz="0.5" />
    </inertial>
  </xacro:macro>

   <xacro:macro name="transmission_block" params="joint_name">
	  <transmission name="tran1">
	    <type>transmission_interface/SimpleTransmission</type>
	    <joint name="${joint_name}">
	      <hardwareInterface>PositionJointInterface</hardwareInterface>
	    </joint>
	    <actuator name="motor1">
	      <hardwareInterface>PositionJointInterface</hardwareInterface>
	      <mechanicalReduction>1</mechanicalReduction>
	    </actuator>
	  </transmission>
   </xacro:macro>

   <xacro:macro name="frictional">
	<gazebo>
	<mu1 value="100.0"/>
        <mu2 value="100.0"/>
	</gazebo>
   </xacro:macro>
<!--==========RIGHT ARM==============-->
<link name="world"/>

<joint name="fixed" type="fixed">
    <parent link="world"/>
    <child link="base"/>
</joint>

<!--		 base 		-->
<link name="base">
    <collision>
    <origin rpy="0 0 0" xyz="0 0 0.05"/>
      	<geometry>
        <mesh filename="package://irl_dual_arm/mesh/arm/base.dae" scale="1 1 1"/>
      	</geometry>
    </collision>
    <visual>
    <origin rpy="0 0 0" xyz="0 0 0.05"/>
 	<geometry>
        <mesh filename="package://irl_dual_arm/mesh/arm/base.dae" scale="1 1 1"/>
      </geometry>
    </visual>
	<xacro:inertial_matrix mass="1000"/>
  </link>

  <joint name="joint1" type="revolute">
    <parent link="base"/>
    <child link="link1"/>
    <origin rpy="1.571 0 1.571" xyz="0.19 0 0.88"/>
    <axis xyz="0 0 1"/> 
    <limit effort="30" lower="-1.0467" upper="3.14" velocity="1.571"/>
    <dynamics damping="50" friction="1"/>
  </joint>

<!-- 		link1 		-->
  <link name="link1">
    <collision>
      <origin rpy="0 0 1.571" xyz="0 0 0"/>
      <geometry>
        <mesh filename="package://irl_dual_arm/mesh/arm/link1.dae" scale="1 1 1"/>
      </geometry>
    </collision>
    <visual>
      <origin rpy="0 0 1.571" xyz="0 0 0"/>
      <geometry>
        <mesh filename="package://irl_dual_arm/mesh/arm/link1.dae" scale="1 1 1"/>
      </geometry>
    </visual>
	<xacro:inertial_matrix mass="1"/>
  </link>


  <joint name="joint2" type="revolute">
    <parent link="link1"/>
    <child link="link2"/>
    <origin rpy="0 1.571 0" xyz="-0.04 0 0.06"/>
    <axis xyz="0 0 1"/>
    <limit effort="30" lower="-2.355" upper="0.3489" velocity="1.571"/>
    <dynamics damping="50" friction="1"/>
  </joint>

<!-- link2 -->
  <link name="link2">
    <collision>
      <origin rpy="0 0 0" xyz="0 0 0"/>
       <geometry>
        <mesh filename="package://irl_dual_arm/mesh/arm/link2.dae" scale="1 1 1"/>
      </geometry>
    </collision>
    <visual>
      <origin rpy="0 0 0" xyz="0 0 0"/>
      <geometry>
        <mesh filename="package://irl_dual_arm/mesh/arm/link2.dae" scale="1 1 1"/>
      </geometry>
    </visual>
	<xacro:inertial_matrix mass="1"/>
  </link>

  <joint name="joint3" type="revolute">
    <parent link="link2"/>
    <child link="link3"/>
    <origin rpy="1.571 0 0" xyz="0 -0.04 0.035"/>		
    <axis xyz="0 0 1"/>
    <limit effort="30" lower="-1.74" upper="0.611" velocity="1.571"/>
    <dynamics damping="50" friction="1"/>
  </joint>

<!-- link3 -->
  <link name="link3">
      <collision>
      <origin rpy="0 0 3.14" xyz="0 0 0"/>
       <geometry>
        <mesh filename="package://irl_dual_arm/mesh/arm/link3.dae" scale="1 1 1"/>
      </geometry>
    </collision>
    <visual>
      <origin rpy="0 0 3.14" xyz="0 0 0"/>
      <geometry>
        <mesh filename="package://irl_dual_arm/mesh/arm/link3.dae" scale="1 1 1"/>
      </geometry>
    </visual>
	<xacro:inertial_matrix mass="1"/>
  </link>

  <joint name="joint4" type="revolute">
    <parent link="link3"/>
    <child link="link4"/>
    <origin rpy="0 -1.571 0" xyz="-0.025 0 0.2"/>
    <axis xyz="0 0 1"/>
    <limit effort="30" lower="0" upper="1.8" velocity="1.571"/>
    <dynamics damping="50" friction="1"/>
  </joint>

<!-- link4 -->
  <link name="link4">
      <collision>
      <origin rpy="3.14 0 -1.571" xyz="0 0 0"/>
       <geometry>
        <mesh filename="package://irl_dual_arm/mesh/arm/link4.dae" scale="1 1 1"/>
      </geometry>
    </collision>
    <visual>
      <origin rpy="3.14 0 -1.571" xyz="0 0 0"/>
      <geometry>
        <mesh filename="package://irl_dual_arm/mesh/arm/link4.dae" scale="1 1 1"/>
      </geometry>
    </visual>
	<xacro:inertial_matrix mass="1"/>
  </link>

  <joint name="joint5" type="revolute">
    <parent link="link4"/>
    <child link="link5"/>
    <origin rpy="0 1.571 0" xyz="0.04 0 -0.025"/>
    <axis xyz="0 0 1"/>
    <limit effort="30" lower="-1.74" upper="1.74" velocity="1.571"/>
    <dynamics damping="50" friction="1"/>
  </joint>

<!-- link5 -->
  <link name="link5">
       <collision>
      <origin rpy="0 0 0" xyz="0 0 0"/>
       <geometry>
        <mesh filename="package://irl_dual_arm/mesh/arm/link5.dae" scale="1 1 1"/>
      </geometry>
    </collision>
    <visual>
      <origin rpy="0 0 0" xyz="0 0 0"/>
      <geometry>
        <mesh filename="package://irl_dual_arm/mesh/arm/link5.dae" scale="1 1 1"/>
      </geometry>
    </visual>
	<xacro:inertial_matrix mass="1"/>
  </link>

<!-- robotis's 3DOF gripper_RIGHT -->

  <joint name="joint6" type="fixed">
    <parent link="link5"/>
    <child link="gr_rbase"/>
    <origin rpy="-1.57 -1.57 0" xyz="0 0 0.19"/>
    <dynamics damping="50" friction="1"/>
  </joint>

  <link name="gr_rbase">
    <collision>
      <origin rpy="-1.57 0 -0.73" xyz="0 -0.028 0"/>
      <geometry>
        <mesh filename="package://irl_dual_arm/mesh/gripper/r_base.dae" scale="1 1 1"/>
      </geometry>
    </collision>
    <visual>
      <origin rpy="-1.57 0 -0.73" xyz="0 -0.028 0"/>
      <geometry>
        <mesh filename="package://irl_dual_arm/mesh/gripper/r_base.dae" scale="1 1 1"/>
      </geometry>
    </visual>
	<xacro:inertial_matrix mass="1"/>
  </link>

<!-- 					-->
  <joint name="r_finger1_1" type="revolute">
    <parent link="gr_rbase"/>
    <child link="r_finger_1_1"/>
    <origin rpy="0 0 0" xyz="0.0475 -0.002 0.0285"/>
    <axis xyz="0 0 1"/>
    <limit effort="30" lower="0" upper="0.7" velocity="1.571"/>
    <dynamics damping="50" friction="1"/>
  </joint>

  <link name="r_finger_1_1">
    <collision>
      <origin rpy="-1.57 0 -1.57" xyz="0 0 0"/>
      <geometry>
        <mesh filename="package://irl_dual_arm/mesh/gripper/r_1_1.dae" scale="1 1 1"/>
      </geometry>
    </collision>
    <visual>
      <origin rpy="-1.57 0 -1.57" xyz="0 0 0"/>
      <geometry>
        <mesh filename="package://irl_dual_arm/mesh/gripper/r_1_1.dae" scale="1 1 1"/>
      </geometry>
    </visual>
	<xacro:inertial_matrix mass="1"/>
	<xacro:frictional/>
  </link>

<!-- 							-->
  <joint name="r_finger1_2" type="revolute">
    <parent link="r_finger_1_1"/>
    <child link="r_finger_1_2"/>
    <origin rpy="0 0 0" xyz="0.05 -0.005 0"/>
    <axis xyz="0 0 1"/>
    <limit effort="30" lower="0" upper="1.4" velocity="1.571"/>
    <dynamics damping="50" friction="1"/>
    <mimic joint="r_finger1_1" multiplier="1.6" offset="0" />
    <!-- gear ratio = 1.4/0.87 -->
  </joint>

  <link name="r_finger_1_2">
    <collision>
      <origin rpy="-1.57 0 -1.57" xyz="0 0 -0.013"/>
      <geometry>
        <mesh filename="package://irl_dual_arm/mesh/gripper/r_1_2.dae" scale="0.001 0.001 0.001"/>
      </geometry>
    </collision>
    <visual>
      <origin rpy="-1.57 0 -1.57" xyz="0 0 -0.013"/>
      <geometry>
        <mesh filename="package://irl_dual_arm/mesh/gripper/r_1_2.dae" scale="0.001 0.001 0.001"/>
      </geometry>
    </visual>
	<xacro:inertial_matrix mass="1"/>
	<xacro:frictional/>
  </link>

<!-- 							-->
  <joint name="r_finger2_1" type="revolute">
    <parent link="gr_rbase"/>
    <child link="r_finger_2_1"/>
    <origin rpy="0 0 0" xyz="0.0475 -0.002 -0.017"/>
    <axis xyz="0 0 1"/>
    <limit effort="30" lower="0" upper="0.7" velocity="1.571"/>
    <dynamics damping="50" friction="1"/>
  </joint>

  <link name="r_finger_2_1">
    <collision>
      <origin rpy="-1.57 0 -1.57" xyz="0 0 0"/>
      <geometry>
        <mesh filename="package://irl_dual_arm/mesh/gripper/r_2_1.dae" scale="1 1 1"/>
      </geometry>
    </collision>
    <visual>
      <origin rpy="-1.57 0 -1.57" xyz="0 0 0"/>
      <geometry>
        <mesh filename="package://irl_dual_arm/mesh/gripper/r_2_1.dae" scale="1 1 1"/>
      </geometry>
    </visual>
	<xacro:inertial_matrix mass="1"/>
	<xacro:frictional/>
  </link>

  <joint name="r_finger2_2" type="revolute">
    <parent link="r_finger_2_1"/>
    <child link="r_finger_2_2"/>
    <origin rpy="0 0 0" xyz="0.05 -0.005 0"/>
    <axis xyz="0 0 1"/>
    <limit effort="30" lower="0" upper="1.4" velocity="1.571"/>
    <dynamics damping="50" friction="1"/>
    <mimic joint="r_finger2_1" multiplier="1.6" offset="0" />
    <!-- gear ratio = 1.4/0.87 -->
  </joint>

  <link name="r_finger_2_2">
    <collision>
      <origin rpy="3.14 -1.57 0" xyz="-0.005 0.001 0.0065"/>
      <geometry>
        <mesh filename="package://irl_dual_arm/mesh/gripper/r_2_2.dae" scale="1 1 1"/>
      </geometry>
    </collision>
    <visual>
      <origin rpy="3.14 -1.57 0" xyz="-0.005 0.001 0.0065"/>
      <geometry>
        <mesh filename="package://irl_dual_arm/mesh/gripper/r_2_2.dae" scale="1 1 1"/>
      </geometry>
    </visual>
	<xacro:inertial_matrix mass="1"/>
	<xacro:frictional/>
  </link>

<!-- 							-->
  <joint name="r_finger3_1" type="revolute">
    <parent link="gr_rbase"/>
    <child link="r_finger_3_1"/>
    <origin rpy="3.14 0 1.57" xyz="0.0185 0.023 0"/>
    <axis xyz="0 0 1"/>
    <limit effort="30" lower="0" upper="0.7" velocity="1.571"/>
    <dynamics damping="50" friction="1"/>
  </joint>

  <link name="r_finger_3_1">
    <collision>
      <origin rpy="1.57 0 1.57" xyz="0 0 0"/>
      <geometry>
        <mesh filename="package://irl_dual_arm/mesh/gripper/r_3_1.dae" scale="1 1 1"/>
      </geometry>
    </collision>
    <visual>
      <origin rpy="1.57 0 1.57" xyz="0 0 0"/>
      <geometry>
        <mesh filename="package://irl_dual_arm/mesh/gripper/r_3_1.dae" scale="1 1 1"/>
      </geometry>
    </visual>
	<xacro:inertial_matrix mass="1"/>
	<xacro:frictional/>
  </link>

  <joint name="r_finger3_2" type="revolute">
    <parent link="r_finger_3_1"/>
    <child link="r_finger_3_2"/>
    <origin rpy="0 0 0" xyz="0.05 -0.005 -0.0065"/>
    <axis xyz="0 0 1"/>
    <limit effort="30" lower="0" upper="1.4" velocity="1.571"/>
    <dynamics damping="50" friction="1"/>
    <mimic joint="r_finger3_1" multiplier="1.6" offset="0" />
    <!-- gear ratio = 1.4/0.87 -->
  </joint>

  <link name="r_finger_3_2">
    <collision>
      <origin rpy="3.14 -1.57 0" xyz="-0.005 0.001 0.0065"/>
      <geometry>
        <mesh filename="package://irl_dual_arm/mesh/gripper/r_3_2.dae" scale="1 1 1"/>
      </geometry>
    </collision>
    <visual>
      <origin rpy="3.14 -1.57 0" xyz="-0.005 0.001 0.0065"/>
      <geometry>
        <mesh filename="package://irl_dual_arm/mesh/gripper/r_3_2.dae" scale="1 1 1"/>
      </geometry>
    </visual>
	<xacro:inertial_matrix mass="1"/>
	<xacro:frictional/>
  </link>

  <!-- Transmissions for ROS Control -->

   <xacro:transmission_block joint_name="joint1"/>
   <xacro:transmission_block joint_name="joint2"/>
   <xacro:transmission_block joint_name="joint3"/>
   <xacro:transmission_block joint_name="joint4"/>
   <xacro:transmission_block joint_name="joint5"/>
   <xacro:transmission_block joint_name="r_finger1_1"/>
   <xacro:transmission_block joint_name="r_finger1_2"/>
   <xacro:transmission_block joint_name="r_finger2_1"/>
   <xacro:transmission_block joint_name="r_finger2_2"/>
   <xacro:transmission_block joint_name="r_finger3_1"/>
   <xacro:transmission_block joint_name="r_finger3_2"/>

  <!-- ros_control plugin -->
  <gazebo>
    <plugin name="gazebo_ros_control" filename="libgazebo_ros_control.so">
      <robotNamespace>/irl_dual_arm</robotNamespace>
    </plugin>
  </gazebo>

</robot>
